<?xml version="1.0"?>
<robot name="amblebot" xmlns:xacro="http://www.ros.org/wiki/xacro">
    <link name="base_link"/>
    <joint name="base_joint" type="fixed">
      <origin rpy="0 0 0" xyz="0 0 0"/>
      <axis xyz="0 0 1"/>
      <parent link="base_link"/>
      <child link="chassis"/>
    </joint>
    <link name="chassis">
      <visual>
        <origin rpy="0 0 0" xyz="0 0 0"/>
        <geometry>
          <cylinder radius="0.0815" length="0.005"/>
        </geometry>
        <material name="blue">
          <color rgba="0.2 0.2 0.8 1.0"/>
        </material>
      </visual>
      <collision>
        <origin rpy="0 0 0" xyz="0 0 0"/>
        <geometry>
          <cylinder radius="0.0817" length="0.007"/>
        </geometry>
        <material name="blue">
          <color rgba="0.2 0.2 0.8 0.5"/>
        </material>
      </collision>
      <inertial>
        <origin rpy="0 0 0" xyz="0.0 0.0 0.0"/>
        <mass value="0.01"/>
        <inertia ixx="2e-08" ixy="0" ixz="0" iyy="3e-08" iyz="0" izz="2e-08"/>
      </inertial>
    </link>

    <xacro:macro name="wheel_assembly" params="side reflect">
    <link name="${side}_wheel">
      <visual>
        <origin rpy="0 0 0" xyz="0 0 0"/>
        <geometry>
          <cylinder radius="0.035" length="0.008"/>
        </geometry>
        <material name="white">
          <color rgba="0.8 0.8 0.8 1"/>
        </material>
      </visual>
      <collision>
        <origin rpy="0 0 0" xyz="0 0 0"/>
        <geometry>
          <cylinder radius="0.035" length="0.008"/>
        </geometry>
        <material name="white">
          <color rgba="0.8 0.8 0.8 1"/>
        </material>
      </collision>
      <inertial>
        <origin rpy="0 0 0" xyz="0.0 0.0 0.0"/>
        <mass value="0.003"/>
        <inertia ixx="2e-08" ixy="0" ixz="0" iyy="3e-08" iyz="0" izz="2e-08"/>
      </inertial>
    </link>

    <joint name="${side}_wheel_joint" type="continuous">
      <origin rpy="${-pi/2*reflect} 0 0" xyz="0.0 ${reflect*0.070} 0.0"/>
      <axis xyz="0 0 1"/>
      <parent link="chassis"/>
      <child link="${side}_wheel"/>
    </joint>
    </xacro:macro>

  <xacro:wheel_assembly side="right" reflect="-1"/>
  <xacro:wheel_assembly side="left" reflect="1"/>
</robot>
